Workbook

Sheet I-1
A2: I. Summary of Business
A3: I-1. Summary of Life Insurance Business by Year
U4: unit: million won,%
A5: 년도 | B5: Business Conditions | E5: Income & Expenditure | J5: Assets | M5: Management Efficiency[%] | U5: Business in Force per Capital(1,000won)
B6: New Business | C6: Lapses & Surrenders | D6: Business in Force | E6: Premium Income | F6: Investment Income | G6: Claims Paid | H6: Operating Expenses | I6: Net Income (or Loss) | J6: Total Assets | L6: Invested Assets | M6: Ratio of New Business | N6: Ratio of Lapses & Surrenders | O6: Increase Ratio of Business in Force | P6: Ratio of Operating Expenses | R6: Profit Rate of Invested Assets | S6: Increase Ratio of Total Assets | T6: Ratio of Invested Assets
K7: Separate Account Assets
A11: 2013 | B11: 282787546 | C11: 172019090 | D11: 2183819487 | E11: 77236745 | F11: 18472547 | G11: 41900225 | H11: 5723872 | I11: 2093193 | J11: 597480091 | K11: 101986862 | L11: 467374120 | M11: 13.4 | N11: 7.2 | O11: 3.4 | P11: 7.4 | R11: 4.6 | S11: 4.9 | T11: 94.3 | U11: 42702
A12: 2014 | B12: 389488956 | C12: 228686847 | D12: 2304878035 | E12: 110575286 | F12: 25761461 | G12: 62251110 | H12: 8043694 | I12: 3236983 | J12: 662075171 | K12: 111662189 | L12: 523087570 | M12: 17.8 | N12: 8.9 | O12: 5.5 | P12: 7.3 | R12: 4.5 | S12: 10.8 | T12: 95 | U12: 44905
A13: 2015 | B13: 395249415 | C13: 232009715 | D13: 2404224008 | E13: 117213653 | F13: 27863264 | G13: 66972365 | H13: 8040393 | I13: 3616895 | J13: 724929682 | K13: 123770179 | L13: 573486517 | M13: 17.1 | N13: 8.6 | O13: 4.3 | P13: 6.9 | R13: 4 | S13: 9.5 | T13: 95.4 | U13: 46657
A14: 2016 | B14: 365289906 | C14: 236401499 | D14: 2470849678 | E14: 119811249 | F14: 29289425 | G14: 71691816 | H14: 8313537 | I14: 2420705 | J14: 782149062 | K14: 132423436 | L14: 622131791 | M14: 15.2 | N14: 8.5 | O14: 2.8 | P14: 6.9 | R14: 3.9 | S14: 7.9 | T14: 95.8 | U14: 47796
A15: 2017 | B15: 322063400 | C15: 238031829 | D15: 2488755794 | E15: 113973482 | F15: 35763483 | G15: 79437498 | H15: 8676171 | I15: 3914952 | J15: 832826894 | K15: 145609158 | L15: 656211118 | M15: 13 | N15: 8.5 | O15: 0.7 | P15: 7.6 | R15: 3.5 | S15: 6.5 | T15: 95.5 | U15: 48065
A17: 2018 | B17: 302769912 | C17: 243657914 | D17: 2473416730 | E17: 110843130 | F17: 32412183 | G17: 86070693 | H17: 9443020 | I17: 4032458 | J17: 857198324 | K17: 143796950 | L17: 687092187 | M17: 12.2 | N17: 8.8 | O17: -0.1 | P17: 8.5 | R17: 3.6 | S17: 2.9 | T17: 96.3 | U17: 47725
A18: 2019 | B18: 300287155 | C18: 249939350 | D18: 2449695976 | E18: 117262358 | F18: 33633494 | G18: 92069277 | H18: 9491772 | I18: 3114040 | J18: 918161402 | K18: 158881010 | L18: 731989699 | M18: 12.1 | N18: 9 | O18: -1 | P18: 8.1 | R18: 3.5 | S18: 7.1 | T18: 96.4 | U18: 47246
A19: 2020 | B19: 309191489 | C19: 237962699 | D19: 2448368003 | E19: 119587220 | F19: 37666528 | G19: 95247277 | H19: 9464913 | I19: 3451340 | J19: 977283599 | K19: 178987876 | L19: 769238507 | M19: 12.6 | N19: 8.6 | O19: -0.1 | P19: 7.9 | R19: 3.1 | S19: 6.4 | T19: 96.4 | U19: 46807
A20: 2021 | B20: 283491779 | C20: 211116795 | D20: 2454417879 | E20: 119421118 | F20: 37427695 | G20: 99173053 | H20: 9357389 | I20: 3726154 | J20: 992404265 | K20: 186241017 | L20: 781888265 | M20: 11.6 | N20: 7.7 | O20: 0.3 | P20: 7.8 | R20: 3.2 | S20: 1.5 | T20: 97 | U20: 47530
A21: 2022 | B21: 266442698 | C21: 216931873 | D21: 2424608591 | E21: 132683691 | F21: 43207616 | G21: 134368168 | H21: 9622170 | I21: 3703681 | J21: 938269945 | K21: 168873397 | L21: 736547607 | M21: 10.9 | N21: 8 | O21: -1.2 | P21: 7.3 | R21: 3.1 | S21: -5.5 | T21: 95.7 | U21: 47136
U24: unit: million won,%
A25: Year | B25: Business Conditions | E25: Business Performance | J25: Assets | M25: Management Efficiency[%] | U25: Business in Force per Capital(1,000won)
B26: New Business | C26: Lapses & Surrenders | D26: Business in Force | E26: Insurance Income | F26: Insurance Service Expenses | G26: Investment Income | H26: Investment Expenses | I26: Net Income (or Loss) | J26: Total Assets | L26: Invested Assets | M26: Ratio of New Business | N26: Ratio of Lapses & Surrenders | O26: Increase Ratio of Business in Force | P26: Ratio of Operating Expenses | R26: Profit Rate of Invested Assets | S26: Increase Ratio of Total Assets | T26: Ratio of Invested Assets
K27: Separate Account Assets | Q27: Operating Expenses
A31: 2023.1 | B31: 28691455 | C31: 21678419 | D31: 2418030100 | E31: 0 | F31: 0 | G31: 0 | H31: 0 | I31: 0 | J31: 855070876 | K31: 102415076 | L31: 736057145 | M31: 1.2 | N31: 0.9 | O31: -0.3 | P31: 10.7 | Q31: 1203184 | R31: 3.1 | S31: -8.867285 | T31: 97.8 | U31: -
A32: 2023.2 | B32: 51769019 | C32: 41419536 | D32: 2414343895 | E32: 0 | F32: 0 | G32: 0 | H32: 0 | I32: 0 | J32: 840173130 | K32: 101315292 | L32: 723670099 | M32: 2.1 | N32: 1.7 | O32: -0.4 | P32: 11.5 | Q32: 2359341 | R32: 3.1 | S32: -10.455074 | T32: 97.9 | U32: -
A33: 2023.3 | B33: 76909418 | C33: 61088691 | D33: 2410369521 | E33: 7639247 | F33: 6154824 | G33: 22938068 | H33: 20642430 | I33: 2726372 | J33: 853976069 | K33: 103014955 | L33: 736591831 | M33: 3.2 | N33: 2.4 | O33: -0.6 | P33: 13.1 | Q33: 3795740 | R33: 3.4 | S33: -8.9839686 | T33: 98.1 | U33: -
A34: 2023.4 | B34: 94978839 | C34: 77582115 | D34: 2406691408 | E34: 7639247 | F34: 6154824 | G34: 22938068 | H34: 20642430 | I34: 2726372 | J34: 856345894 | K34: 103406648 | L34: 738974142 | M34: 3.9 | N34: 3.1 | O34: -0.7 | P34: 13.9 | Q34: 5082657 | R34: 3.4 | S34: -8.7313947 | T34: 98.1 | U34: -
A35: 2023.5 | B35: 112745321 | C35: 94230576 | D35: 2403239291 | E35: 7639247 | F35: 6154824 | G35: 22938068 | H35: 20642430 | I35: 2726372 | J35: 849104080 | K35: 104151688 | L35: 730928176 | M35: 4.6 | N35: 3.7 | O35: -0.9 | P35: 16.5 | Q35: 7274715 | R35: 3.4 | S35: -9.5032209 | T35: 98.1 | U35: -
A36: 2023.6 | B36: 131040684 | C36: 112482192 | D36: 2398192941 | E36: 15309840 | F36: 12084804 | G36: 34480228 | H36: 32333546 | I36: 3829374 | J36: 845909499 | K36: 104123151 | L36: 728146167 | M36: 5.4 | N36: 4.4 | O36: -1.1 | P36: 17 | Q36: 8922667 | R36: 3.4 | S36: -9.8435035 | T36: 98.2 | U36: -
A37: 2023.7 | B37: 149765537 | C37: 129485085 | D37: 2393785550 | E37: 15309840 | F37: 12084804 | G37: 34480228 | H37: 32333546 | I37: 3829374 | J37: 843444714 | K37: 104622202 | L37: 724054515 | M37: 6.2 | N37: 5 | O37: -1.3 | P37: 17.4 | Q37: 10543897 | R37: 3.4 | S37: -10.1 | T37: 98 | U37: -
A38: 2023.8 | B38: 169314711 | C38: 146753401 | D38: 2391510987 | E38: 15309840 | F38: 12084804 | G38: 34480228 | H38: 32333546 | I38: 3829374 | J38: 839917184 | K38: 103531591 | L38: 721752781 | M38: 7 | N38: 5.7 | O38: -1.4 | P38: 17.9 | Q38: 12290743 | R38: 3.4 | S38: -10.5 | T38: 98 | U38: -
A39: 2023.9 | B39: 185870006 | C39: 162142864 | D39: 2387004773 | E39: 23517956 | F39: 18806231 | G39: 45865547 | H39: 44263101 | I39: 4399289 | J39: 831370568 | K39: 100541112 | L39: 716755094 | M39: 7.6 | N39: 6.2 | O39: -1.6 | P39: 18 | Q39: 13797749 | R39: 3.3 | S39: -11.393243 | T39: 98.1 | U39: -
A40: 2023.10 | B40: 203096721 | C40: 178589508 | D40: 2380220442 | E40: 23517956 | F40: 18806231 | G40: 45865547 | H40: 44263101 | I40: 4399289 | J40: 819257787 | K40: 97844631 | L40: 707098888 | M40: 8.4 | N40: 6.8 | O40: -1.8 | P40: 18.1 | Q40: 15230531 | R40: 3.3 | S40: -12.7 | T40: 98 | U40: -
A41: 2023.11 | B41: 220554604 | C41: 196038487 | D41: 2376582804 | E41: 23517956 | F41: 18806231 | G41: 45865547 | H41: 44263101 | I41: 4399289 | J41: 847900994 | K41: 102270426 | L41: 729265852 | M41: 9.1 | N41: 7.4 | O41: -2 | P41: 17.9 | Q41: 16702976 | R41: 3.3 | S41: -9.6314448 | T41: 97.8 | U41: -
A44: * The number of Business Performance is counted quarterly based on the Business Reports.

Sheet I-2
A2: I. Summary of Business
A3: I-2. Summary of Business by Company
A6: 2023. 1. 1. - 2023. 11. 30. | L6: unit: million won
B7: Business Conditions | E7: Business Performance | J7: Assets
B8: New Business | C8: Lapses & Surrenders | D8: Business in Force | E8: Insurance Income | F8: Insuracne Service Expenses | G8: Investment Income | H8: Investment Expenses | I8: Net Income (or Loss) | J8: Total Assets | K8: S/A | L8: Invested Assets
A12: Hanwha | B12: 27116048 | C12: 22609052 | D12: 308629683 | E12: 3438764 | F12: 2758462 | G12: 6253018 | H12: 6153939 | I12: 577893 | J12: 110517438 | K12: 14902694 | L12: 93638722
A13: ABL | B13: 10346347 | C13: 4670498 | D13: 52678079 | E13: 494992 | F13: 433027 | G13: 1053378 | H13: 1014900 | I13: 37534 | J13: 16802779 | K13: 2300273 | L13: 14071550
A14: Samsung | B14: 39336512 | C14: 42052308 | D14: 614241340 | E14: 6295962 | F14: 5032457 | G14: 12538587 | H14: 12414734 | I14: 1126063 | J14: 267795942 | K14: 26561902 | L14: 237238425
A15: Heungkuk | B15: 2180946 | C15: 6367703 | D15: 66674486 | E15: 694518 | F15: 582813 | G15: 1235081 | H15: 1220204 | I15: 87278 | J15: 24550015 | K15: 1232914 | L15: 22989647
A16: Kyobo | B16: 37564522 | C16: 23843825 | D16: 304379585 | E16: 2742682 | F16: 2530495 | G16: 6677690 | H16: 6061876 | I16: 602859 | J16: 107498252 | K16: 15054431 | L16: 90660052
A17: DGB | B17: 3076000 | C17: 2308929 | D17: 16051701 | E17: 183761 | F17: 115286 | G17: 416309 | H17: 403538 | I17: 55022 | J17: 5754026 | K17: 1114498 | L17: 4408169
A18: MiraeAsset | B18: 4820813 | C18: 8699925 | D18: 84591328 | E18: 676812 | F18: 515344 | G18: 2798236 | H18: 2701461 | I18: 159231 | J18: 32259330 | K18: 11978736 | L18: 19292534
A19: KDB | B19: 2480004 | C19: 4212466 | D19: 47372044 | E19: 357041 | F19: 361521 | G19: 776368 | H19: 782396 | I19: -17908 | J19: 16861946 | K19: 694695 | L19: 15796816
A20: DB | B20: 3722629 | C20: 3801461 | D20: 44459999 | E20: 467860 | F20: 374242 | G20: 667304 | H20: 603054 | I20: 115095 | J20: 9690619 | K20: 1155015 | L20: 8188124
A21: Tongyang | B21: 6743962 | C21: 7700843 | D21: 87847908 | E21: 824909 | F21: 624537 | G21: 1620706 | H21: 1529518 | I21: 217494 | J21: 31626403 | K21: 1142747 | L21: 29937314
A22: MetLife | B22: 5568547 | C22: 6343164 | D22: 69268299 | E22: 669570 | F22: 477293 | G22: 2136029 | H22: 2037911 | I22: 221829 | J22: 21996546 | K22: 10894512 | L22: 10808046
A23: KBLife | B23: 5995036 | C23: 7217659 | D23: 84871443 | E23: 566025 | F23: 332037 | G23: 1587366 | H23: 1397487 | I23: 296874 | J23: 30470741 | K23: 5656279 | L23: 24201451
... A39: 2023.8 | B39: 169314711 | C39: 146753401 | D39: 2391510987 | E39: 15309840 | F39: 12084804 | G39: 34480228 | H39: 32333546 | I39: 3829374 | J39: 839917184 | K39: 103531591 | L39: 721752781
A42: * The number of Business Performance is counted quarterly based on the Business Reports.

Sheet I-3
A2: I. Summary of Business
A3: I-3. Management Efficiency
A6: ='I-2'!A6 -> 2023. 1. 1. - 2023. 11. 30. | P6: unit: %
B7: Ratio of New Business | C7: Ratio of Lapses & Surrenders | D7: Increase Ratio of Business in Force | E7: Ratio of Claim paid | H7: Average Insured Amount | J7: Average Premiums of New Business(won) (per 10 thousand won of New Business) | K7: Ratio of Operating Expenses | M7: Profit Rate of Invested Assets | N7: Adjusted Profit Rate of Invested Assets | O7: Increase Ratio of Total Assets | P7: Ratio of Invested Assets
L8: Operating Expenses
H9: New Business(10 thousand won) | I9: Business in Force(10 thousand won)
E11: G/A | F11: S/A | G11: Total
A13: Hanwha | B13: 8.8 | C13: 6.7 | D13: -0.2 | E13: 108.5 | F13: 129.1 | G13: 113.2 | H13: 2143 | I13: 2684 | J13: 175 | K13: 25.6 | L13: 2920806 | M13: 2.8 | N13: 2.6 | O13: -12.827486 | P13: 97.9
A14: ABL | B14: 17.4 | C14: 6.7 | D14: -11.4 | E14: 107.9 | F14: 127.4 | G14: 112.4 | H14: 1189 | I14: 2270 | J14: 541 | K14: 18.8 | L14: 405197 | M14: 3.5 | N14: 3.3 | O14: -13.106372 | P14: 97
A15: Samsung | B15: 6.3 | C15: 6.3 | D15: -2.3 | E15: 116 | F15: 131.6 | G15: 120.6 | H15: 1690 | I15: 3252 | J15: 868 | K15: 16.9 | L15: 3702360 | M15: 3.5 | N15: 3.7 | O15: -4.8675954 | P15: 98.3
A16: Heungkuk | B16: 3 | C16: 8.6 | D16: -7.3 | E16: 150.1 | F16: 152.2 | G16: 150.7 | H16: 921 | I16: 2328 | J16: 3994 | K16: 15.2 | L16: 436662 | M16: 4.4 | N16: 4.2 | O16: -20.940394 | P16: 98.6
A17: Kyobo | B17: 12.5 | C17: 7 | D17: 1.1 | E17: 76.3 | F17: 131.5 | G17: 91.2 | H17: 1161 | I17: 3249 | J17: 1186 | K17: 14.4 | L17: 1982222 | M17: 4 | N17: 3.8 | O17: -8.2589261 | P17: 98.1
A18: DGB | B18: 16 | C18: 10.4 | D18: -16.3 | E18: 119 | F18: 43.9 | G18: 90.3 | H18: 1132 | I18: 2798 | J18: 272 | K18: 27.6 | L18: 226119 | M18: 3.5 | N18: 3 | O18: -10.324944 | P18: 95
A19: MiraeAsset | B19: 5.3 | C19: 9.2 | D19: -6.1 | E19: 132.5 | F19: 102.6 | G19: 114.4 | H19: 2574 | I19: 2817 | J19: 433 | K19: 15.2 | L19: 484695 | M19: 2.6 | N19: 2.5 | O19: -13.301454 | P19: 95.1
A20: KDB | B20: 5 | C20: 8 | D20: -5.1 | E20: 119.8 | F20: 111.1 | G20: 118.8 | H20: 3151 | I20: 2857 | J20: 74 | K20: 16.3 | L20: 307362 | M20: 2.5 | N20: 2.3 | O20: -17.228199 | P20: 97.7
A21: DB | B21: 8.3 | C21: 7.8 | D21: -1 | E21: 59.7 | F21: 89.4 | G21: 64.1 | H21: 2299 | I21: 2847 | J21: 127 | K21: 29.7 | L21: 507025 | M21: 3.3 | N21: 3.1 | O21: -23.716144 | P21: 95.9
A22: Tongyang | B22: 7.4 | C22: 7.9 | D22: -3.1 | E22: 138.3 | F22: 86.1 | G22: 129.6 | H22: 1444 | I22: 2139 | J22: 749 | K22: 17 | L22: 675505 | M22: 3 | N22: 2.8 | O22: -15.515379 | P22: 98.2
A23: MetLife | B23: 7.9 | C23: 8.3 | D23: -1.8 | E23: 55.5 | F23: 84.3 | G23: 74.3 | H23: 4466 | I23: 4399 | J23: 624 | K23: 19.4 | L23: 589407 | M23: 1.4 | N23: 1.3 | O23: -6.4819384 | P23: 97.4
A24: KBLife | B24: 6.9 | C24: 7.8 | D24: -1.9 | E24: 79.3 | F24: 80 | G24: 79.5 | H24: 3821 | I24: 4977 | J24: 251 | K24: 20.3 | L24: 722605 | M24: 4.7 | N24: 4.2 | O24: -8.1148007 | P24: 97.5
... A36: Total | B36: 9.1 | C36: 7.4 | D36: -2 | E36: 107.2 | F36: 109.8 | G36: 108 | H36: 1585 | I36: 2807 | J36: 711 | K36: 17.9 | L36: 16702976 | M36: 3.3 | N36: 3.2 | O36: -9.6314448 | P36: 97.8
A38: ='I-2'!A37 -> 2023.10 | B38: 8.4 | C38: 6.8 | D38: -1.8 | E38: 108.8 | F38: 111.2 | G38: 109.5 | H38: 1573 | I38: 2810 | J38: 679 | K38: 18.1 | L38: 15230531 | M38: 3.3 | N38: 3.2 | O38: -12.684213 | P38: 98
A39: ='I-2'!A38 -> 2023.9 | B39: 7.7 | C39: 6.2 | D39: -1.6 | E39: 110.1 | F39: 112.3 | G39: 110.8 | H39: 1566 | I39: 2814 | J39: 675 | K39: 18 | L39: 13797753 | M39: 3.3 | N39: 3.2 | O39: -11.4 | P39: 98.1
A40: ='I-2'!A39 -> 2023.8 | B40: 7 | C40: 5.7 | D40: -1.4 | E40: 112.6 | F40: 114.3 | G40: 113.1 | H40: 1585 | I40: 2811 | J40: 665 | K40: 17.9 | L40: 12290743 | M40: 3.4 | N40: 3.3 | O40: -10.5 | P40: 98

Sheet II-1
A2: II. Financial Statement
A3: II-1. Balance Sheets(Total)
A6: 2023. 11. 30. | AX6: unit: million won
D7: Securities | V7: Non Operating Assets | AE7: Total Assets | AF7: Liabilities | AQ7: Shareholders' Equity | AX7: Total Liabilities & Total Shareholders' Equity
B8: Cash & Deposits | D8: Stocks | E8: Government /Public Bonds | F8: Corporate Bonds | G8: Investment Funds | H8: Securities in Foreign Currency | I8: Others | L8: Loans | N8: Loan Secured by Real Estate | O8: Unsecured Loans | P8: Real Estate | R8: Lands | S8: Building | T8: Invested Assets | V8: Insurance Contract Assets | W8: Other Accounts Receivable | X8: Advanced Payment | Y8: Leasehold & Other Deposits | Z8: Others | AC8: Separate Acount Assets | AF8: Insurance Contract Liability | AM8: Policyholder's Equity Adjustment | AN8: Others | AO8: Separate Account Liabilities | AP8: Total Liabilities | AQ8: Capital Stock | AR8: Capital Surplus | AS8: Hybrid Bond | AT8: Retained Adjustment | AU8: Capital Adjustment | AV8: Accumulated Other Comprehensive Income | AW8: Total Shareholder's Equity
J9: Total | AA9: Total | AG9: Policy Loans | AH9: Remaining Coverage | AK9: Incurred Claims
AH10: Best Estimate Liability | AI10: Risk Adjustment | AJ10: Contractual Service Margin | AK10: Best Estimate Liability | AL10: Risk Adjustment
C12: % | K12: % | M12: % | Q12: % | U12: % | AB12: % | AD12: %
A14: Hanwha | B14: 831573 | C14: 0.8 | D14: 3075545 | E14: 38062775 | F14: 4989609 | G14: 13114593 | H14: 11933663 | I14: 1376729 | J14: 73379589 | K14: 66.4 | L14: 16547897 | M14: 15 | N14: 8275370 | O14: 6848423 | P14: 2879663 | Q14: 2.6 | R14: 1790138 | S14: 1078839 | T14: 93638722 | U14: 84.7 | V14: 0 | W14: 1130493 | X14: 141550 | Y14: 19867 | Z14: 684112 | AA14: 1976022 | AB14: 1.8 | AC14: 14902694 | AD14: 13.5 | AE14: 110517438 | AF14: 70775115 | AG14: 9029216 | AH14: 56544030 | AI14: 1631319 | AJ14: 9944019 | AK14: 2619206 | AL14: 24735 | AM14: 9226 | AN14: 12792165 | AO14: 14932432 | AP14: 98508938 | AQ14: 4342650 | AR14: 485281 | AS14: 498344 | AT14: 6390928 | AU14: -1122998 | AV14: 1414295 | AW14: 12008500 | AX14: 110517438
A15: ABL | B15: 91275 | C15: 0.5 | D15: 66537 | E15: 8119167 | F15: 895318 | G15: 2277580 | H15: 899069 | I15: 246438 | J15: 12523009 | K15: 74.5 | L15: 1280141 | M15: 7.6 | N15: 39093 | O15: 282 | P15: 177125 | Q15: 1.1 | R15: 74181 | S15: 112523 | T15: 14071550 | U15: 83.7 | V15: 0 | W15: 148387 | X15: 74042 | Y15: 9561 | Z15: 198967 | AA15: 430956 | AB15: 2.6 | AC15: 2300273 | AD15: 13.7 | AE15: 16802779 | AF15: 13016004 | AG15: 922041 | AH15: 11197492 | AI15: 218622 | AJ15: 990139 | AK15: 607827 | AL15: 1924 | AM15: -1012 | AN15: 520962 | AO15: 2318238 | AP15: 15854192 | AQ15: 15534 | AR15: 1001053 | AS15: 0 | AT15: -442425 | AU15: 0 | AV15: 374425 | AW15: 948587 | AX15: 16802779
A16: Samsung | B16: 1965913 | C16: 0.7 | D16: 44548504 | E16: 85722630 | F16: 14058017 | G16: 7814813 | H16: 20726260 | I16: 837094 | J16: 184869992 | K16: 69 | L16: 46569255 | M16: 17.4 | N16: 33256464 | O16: 7552948 | P16: 3833264 | Q16: 1.4 | R16: 1806237 | S16: 1957719 | T16: 237238425 | U16: 88.6 | V16: 0 | W16: 1456380 | X16: 310382 | Y16: 94133 | Z16: 2134720 | AA16: 3995615 | AB16: 1.5 | AC16: 26561902 | AD16: 9.9 | AE16: 267795942 | AF16: 155077009 | AG16: 17935821 | AH16: 135298455 | AI16: 3134180 | AJ16: 12335579 | AK16: 4281833 | AL16: 26961 | AM16: 8233710 | AN16: 40325314 | AO16: 26587987 | AP16: 230224019 | AQ16: 100000 | AR16: 6131 | AS16: 0 | AT16: 13279848 | AU16: -2110369 | AV16: 26296313 | AW16: 37571923 | AX16: 267795942
A17: Heungkuk | B17: 423130 | C17: 1.7 | D17: 298648 | E17: 6247459 | F17: 2713706 | G17: 4605254 | H17: 2618343 | I17: 335846 | J17: 16819257 | K17: 68.5 | L17: 4865282 | M17: 19.8 | N17: 951734 | O17: 3278355 | P17: 881978 | Q17: 3.6 | R17: 643581 | S17: 238845 | T17: 22989647 | U17: 93.6 | V17: 0 | W17: 128040 | X17: 63738 | Y17: 12829 | Z17: 122847 | AA17: 327454 | AB17: 1.3 | AC17: 1232914 | AD17: 5 | AE17: 24550015 | AF17: 17207569 | AG17: 1424153 | AH17: 12908072 | AI17: 308198 | AJ17: 2189878 | AK17: 1797972 | AL17: 3448 | AM17: -7833 | AN17: 4494927 | AO17: 1232512 | AP17: 22927174 | AQ17: 80120 | AR17: 298227 | AS17: 49650 | AT17: 757943 | AU17: 0 | AV17: 436901 | AW17: 1622841 | AX17: 24550015
A18: Kyobo | B18: 2013800 | C18: 1.9 | D18: 2116376 | E18: 30483921 | F18: 7016626 | G18: 13877793 | H18: 13473460 | I18: 658048 | J18: 67848168 | K18: 63.1 | L18: 18841241 | M18: 17.5 | N18: 6664210 | O18: 10761997 | P18: 1956842 | Q18: 1.8 | R18: 1379350 | S18: 634214 | T18: 90660052 | U18: 84.3 | V18: 0 | W18: 735228 | X18: 166107 | Y18: 43077 | Z18: 839358 | AA18: 1783770 | AB18: 1.7 | AC18: 15054431 | AD18: 14 | AE18: 107498252 | AF18: 68505855 | AG18: 8258813 | AH18: 58084148 | AI18: 1202721 | AJ18: 6483540 | AK18: 2711198 | AL18: 24248 | AM18: 59681 | AN18: 13710692 | AO18: 15074729 | AP18: 97350957 | AQ18: 102500 | AR18: 365936 | AS18: 1607440 | AT18: 6489781 | AU18: -197415 | AV18: 1779052 | AW18: 10147295 | AX18: 107498252
A19: DGB | B19: 53435 | C19: 0.9 | D19: 0 | E19: 2001458 | F19: 567637 | G19: 572366 | H19: 952280 | I19: 106152 | J19: 4251353 | K19: 73.9 | L19: 102648 | M19: 1.8 | N19: 0 | O19: 1 | P19: 733 | Q19: 0 | R19: 107 | S19: 626 | T19: 4408169 | U19: 76.6 | V19: 0 | W19: 79702 | X19: 14151 | Y19: 9824 | Z19: 127683 | AA19: 231359 | AB19: 4 | AC19: 1114498 | AD19: 19.4 | AE19: 5754026 | AF19: 3776254 | AG19: 440295 | AH19: 2778483 | AI19: 87706 | AJ19: 804154 | AK19: 105279 | AL19: 631 | AM19: -64 | AN19: 143375 | AO19: 1125309 | AP19: 5044873 | AQ19: 302282 | AR19: 211442 | AS19: 94880 | AT19: 162639 | AU19: 0 | AV19: -62090 | AW19: 709153 | AX19: 5754026
A20: MiraeAsset | B20: 202326 | C20: 0.6 | D20: 316255 | E20: 8949416 | F20: 461379 | G20: 4585968 | H20: 1511817 | I20: 125093 | J20: 15949928 | K20: 49.4 | L20: 3068042 | M20: 9.5 | N20: 871594 | O20: 420085 | P20: 72238 | Q20: 0.2 | R20: 6841 | S20: 65476 | T20: 19292534 | U20: 59.8 | V20: 0 | W20: 795753 | X20: 54159 | Y20: 5728 | Z20: 132419 | AA20: 988060 | AB20: 3.1 | AC20: 11978736 | AD20: 37.1 | AE20: 32259330 | AF20: 12896853 | AG20: 1492275 | AH20: 10077942 | AI20: 383855 | AJ20: 2052316 | AK20: 377454 | AL20: 5286 | AM20: -1342 | AN20: 4382019 | AO20: 12057931 | AP20: 29335461 | AQ20: 990715 | AR20: 181384 | AS20: 0 | AT20: 1741892 | AU20: -371175 | AV20: 381053 | AW20: 2923869 | AX20: 32259330
A21: KDB | B21: 210483 | C21: 1.2 | D21: 66358 | E21: 6422114 | F21: 973732 | G21: 3273324 | H21: 2562192 | I21: 256604 | J21: 13554324 | K21: 80.4 | L21: 1949445 | M21: 11.6 | N21: 485162 | O21: 31926 | P21: 82564 | Q21: 0.5 | R21: 18306 | S21: 66657 | T21: 15796816 | U21: 93.7 | V21: 0 | W21: 208685 | X21: 30474 | Y21: 9275 | Z21: 122001 | AA21: 370435 | AB21: 2.2 | AC21: 694695 | AD21: 4.1 | AE21: 16861946 | AF21: 14899668 | AG21: 1345667 | AH21: 13200897 | AI21: 191311 | AJ21: 548011 | AK21: 956924 | AL21: 2525 | AM21: -3389 | AN21: 707051 | AO21: 703717 | AP21: 16307046 | AQ21: 199309 | AR21: 654205 | AS21: 215790 | AT21: -233407 | AU21: -54740 | AV21: -226257 | AW21: 554900 | AX21: 16861946
A22: DB | B22: 87105 | C22: 0.9 | D22: 110579 | E22: 1308749 | F22: 943817 | G22: 1477971 | H22: 1076940 | I22: 31413 | J22: 5133165 | K22: 53 | L22: 2743059 | M22: 28.3 | N22: 344647 | O22: 863860 | P22: 224796 | Q22: 2.3 | R22: 210043 | S22: 14753 | T22: 8188124 | U22: 84.5 | V22: 0 | W22: 191112 | X22: 27884 | Y22: 16609 | Z22: 111874 | AA22: 347480 | AB22: 3.6 | AC22: 1155015 | AD22: 11.9 | AE22: 9690619 | AF22: 5723439 | AG22: 1085689 | AH22: 3524082 | AI22: 262924 | AJ22: 1766384 | AK22: 168025 | AL22: 2023 | AM22: -25 | AN22: 899358 | AO22: 1145000 | AP22: 7767772 | AQ22: 253334 | AR22: 154492 | AS22: 39839 | AT22: 1700491 | AU22: -104047 | AV22: -121261 | AW22: 1922848 | AX22: 9690619
A23: Tongyang | B23: 605485 | C23: 1.9 | D23: 158205 | E23: 10304719 | F23: 4149113 | G23: 3174987 | H23: 3996254 | I23: 746342 | J23: 22629020 | K23: 71.6 | L23: 6388643 | M23: 20.2 | N23: 1832839 | O23: 56857 | P23: 314166 | Q23: 1 | R23: 292730 | S23: 54785 | T23: 29937314 | U23: 94.7 | V23: 0 | W23: 313751 | X23: 54335 | Y23: 13894 | Z23: 164362 | AA23: 546342 | AB23: 1.7 | AC23: 1142747 | AD23: 3.6 | AE23: 31626403 | AF23: 24141110 | AG23: 1959430 | AH23: 19156726 | AI23: 443366 | AJ23: 2639653 | AK23: 1895892 | AL23: 5473 | AM23: 783 | AN23: 3230313 | AO23: 1125531 | AP23: 28497736 | AQ23: 806793 | AR23: 463680 | AS23: 344567 | AT23: 1334471 | AU23: -60667 | AV23: 239822 | AW23: 3128667 | AX23: 31626403
A24: MetLife | B24: 404126 | C24: 1.8 | D24: 26580 | E24: 7522063 | F24: 519554 | G24: 102590 | H24: 1361752 | I24: 45 | J24: 9532586 | K24: 43.3 | L24: 869957 | M24: 4 | N24: 619656 | O24: 137094 | P24: 1377 | Q24: 0 | R24: 59 | S24: 1318 | T24: 10808046 | U24: 49.1 | V24: 16121 | W24: 87361 | X24: 46019 | Y24: 29363 | Z24: 115123 | AA24: 293987 | AB24: 1.3 | AC24: 10894512 | AD24: 49.5 | AE24: 21996546 | AF24: 5077160 | AG24: 1036827 | AH24: 2469762 | AI24: 312514 | AJ24: 2174446 | AK24: 117322 | AL24: 3109 | AM24: 5 | AN24: 1155845 | AO24: 10940780 | AP24: 17173791 | AQ24: 141570 | AR24: 68154 | AS24: 0 | AT24: 4150685 | AU24: 0 | AV24: 462346 | AW24: 4822755 | AX24: 21996546
A25: KBLife | B25: 658292 | C25: 2.2 | D25: 135367 | E25: 16291533 | F25: 1390635 | G25: 2642842 | H25: 1477144 | I25: 318885 | J25: 22256405 | K25: 73 | L25: 1201543 | M25: 3.9 | N25: 372100 | O25: 395601 | P25: 85211 | Q25: 0.3 | R25: 56526 | S25: 28684 | T25: 24201451 | U25: 79.4 | V25: 0 | W25: 287953 | X25: 7990 | Y25: 6635 | Z25: 310433 | AA25: 613011 | AB25: 2 | AC25: 5656279 | AD25: 18.6 | AE25: 30470741 | AF25: 16771855 | AG25: 2051494 | AH25: 12832674 | AI25: 435736 | AJ25: 3275886 | AK25: 216630 | AL25: 10929 | AM25: 0 | AN25: 2430197 | AO25: 5633074 | AP25: 24835126 | AQ25: 162015 | AR25: 901319 | AS25: 49800 | AT25: 3003962 | AU25: 0 | AV25: 1518519 | AW25: 5635615 | AX25: 30470741
... A37: Total | B37: 11111088 | C37: 1.3 | D37: 51237332 | E37: 298313224 | F37: 59853498 | G37: 73292503 | H37: 83562444 | I37: 6412397 | J37: 585390507 | K37: 69 | L37: 121184512 | M37: 14.3 | N37: 59889329 | O37: 35428749 | P37: 11579745 | Q37: 1.4 | R37: 6841275 | S37: 4770006 | T37: 729265852 | U37: 86 | V37: 217182 | W37: 7789189 | X37: 1340852 | Y37: 371590 | Z37: 6645904 | AA37: 16364716 | AB37: 1.9 | AC37: 102270426 | AD37: 12.1 | AE37: 847900994 | AF37: 522055501 | AG37: 59549910 | AH37: 431085002 | AI37: 10898586 | AJ37: 60462911 | AK37: 19455965 | AL37: 148713 | AM37: 8221247 | AN37: 109087523 | AO37: 102488333 | AP37: 741852604 | AQ37: 12214939 | AR37: 10300703 | AS37: 3979337 | AT37: 51960998 | AU37: -4021907 | AV37: 31614320 | AW37: 106048390 | AX37: 847900994
A39: ='I-2'!A37 -> 2023.10 | B39: 9680558 | C39: 1.2 | D39: 48112410 | E39: 281695318 | F39: 59310019 | G39: 72019500 | H39: 83093508 | I39: 6658148 | J39: 563599272 | K39: 68.8 | L39: 122244338 | M39: 14.9 | N39: 60433097 | O39: 35718224 | P39: 11574720 | Q39: 1.4 | R39: 6839741 | S39: 4767600 | T39: 707098888 | U39: 86.3 | V39: 247534 | W39: 7538267 | X39: 1383951 | Y39: 372077 | Z39: 4772439 | AA39: 14314268 | AB39: 1.7 | AC39: 97844631 | AD39: 11.9 | AE39: 819257787 | AF39: 496083396 | AG39: 56891171 | AH39: 405790635 | AI39: 10802380 | AJ39: 59822464 | AK39: 19512308 | AL39: 148877 | AM39: 5196794 | AN39: 114737470 | AO39: 97979838 | AP39: 713997498 | AQ39: 12214939 | AR39: 10300703 | AS39: 3979337 | AT39: 50632729 | AU39: -4022012 | AV39: 32154592 | AW39: 105260289 | AX39: 819257787
A40: ='I-2'!A38 -> 2023.9 | B40: 9696287 | C40: 1.2 | D40: 48883484 | E40: 288857134 | F40: 60669592 | G40: 69857501 | H40: 84593157 | I40: 7065618 | J40: 572591546 | K40: 68.9 | L40: 122887345 | M40: 14.8 | N40: 60997297 | O40: 35743127 | P40: 11579916 | Q40: 1.4 | R40: 6854696 | S40: 4781178 | T40: 716755094 | U40: 86.2 | V40: 247574 | W40: 7325414 | X40: 1364676 | Y40: 372408 | Z40: 4764266 | AA40: 14074338 | AB40: 1.7 | AC40: 100541112 | AD40: 12.1 | AE40: 831370543 | AF40: 503749907 | AG40: 57182051 | AH40: 413916995 | AI40: 10902571 | AJ40: 59094786 | AK40: 19675155 | AL40: 150947 | AM40: 6271193 | AN40: 113736603 | AO40: 100867616 | AP40: 724625319 | AQ40: 12214939 | AR40: 10300724 | AS40: 3979337 | AT40: 50746191 | AU40: -4022120 | AV40: 33526153 | AW40: 106745225 | AX40: 831370543
A41: ='I-2'!A39 -> 2023.8 | B41: 9727080 | C41: 1.2 | D41: 48156167 | E41: 294409007 | F41: 61188076 | G41: 69816781 | H41: 85736473 | I41: 6690047 | J41: 577588108 | K41: 68.8 | L41: 122846825 | M41: 14.6 | N41: 61064230 | O41: 35653939 | P41: 11590768 | Q41: 1.4 | R41: 6854695 | S41: 4781147 | T41: 721752781 | U41: 85.9 | V41: 219569 | W41: 8081307 | X41: 1103773 | Y41: 373013 | Z41: 4855150 | AA41: 14632813 | AB41: 1.7 | AC41: 103531591 | AD41: 12.3 | AE41: 839917184 | AF41: 510542394 | AG41: 58309727 | AH41: 420225159 | AI41: 11134629 | AJ41: 59366392 | AK41: 19660028 | AL41: 142714 | AM41: 6392573 | AN41: 112750677 | AO41: 103642470 | AP41: 733328114 | AQ41: 12134211 | AR41: 10282582 | AS41: 3979337 | AT41: 50927466 | AU41: -4019216 | AV41: 33284689 | AW41: 106589070 | AX41: 839917184

Sheet II-2
A2: II. Financial Statement
A3: II-2. Statement of Comprehensive Income(Total)
A6: 2023. 3/4Q | X6: unit: million won
B7: Insurance Profit and Loss | O7: Investment Profit and Loss | U7: Other Profit and Loss | W7: Income Tax Expenses | X7: Net Income [or Loss]
B8: Insurance Revenue | H8: Insurance Service Expenses | L8: Reinsurance Income | M8: Reinsurance Service Expenses | N8: Other Business Expenses | O8: Investment Income | R8: Investment Expenses | U8: Non Operating Income | V8: Non Operating Expenses
B9: Expected Insurance Payment | C9: Expected Operating Expenses | D9: Changes in Risk Adjustment | E9: CSM Amortization | F9: Others | G9: Sub Total | H9: Incurred Insurance Payment | I9: Incurred Operating Expenses | J9: Others | K9: Sub Total | O9: Insurance Finance Income | P9: Others | Q9: Sub Total | R9: Insurance Finance Expenses | S9: Others | T9: Sub Total
A13: Hanwha | B13: 3438764 | C13: 1723947 | D13: 455991 | E13: 92337 | F13: 668341 | G13: 498147 | H13: 2758462 | I13: 1733555 | J13: 466778 | K13: 558129 | L13: 174940 | M13: 179780 | N13: 110924 | O13: 6253018 | P13: 566 | Q13: 6252451 | R13: 6153939 | S13: 2519057 | T13: 3634882 | U13: 12855 | V13: 5575 | W13: 93006 | X13: 577893
A14: ABL | B14: 494992 | C14: 266921 | D14: 68032 | E14: 11720 | F14: 75180 | G14: 73140 | H14: 433027 | I14: 280825 | J14: 76371 | K14: 75832 | L14: 33801 | M14: 43257 | N14: 16894 | O14: 1053378 | P14: -2154 | Q14: 1055532 | R14: 1014900 | S14: 497054 | T14: 517846 | U14: 444 | V14: 24353 | W14: 12649 | X14: 37534
A15: Samsung | B15: 6295962 | C15: 3342664 | D15: 1288759 | E15: 387159 | F15: 987090 | G15: 290290 | H15: 5032457 | I15: 3293398 | J15: 1407451 | K15: 331608 | L15: 98052 | M15: 117806 | N15: 37686 | O15: 12538587 | P15: 1022497 | Q15: 11516090 | R15: 12414734 | S15: 6987408 | T15: 5427326 | U15: 173091 | V15: 156385 | W15: 220561 | X15: 1126063
A16: Heungkuk | B16: 694518 | C16: 313750 | D16: 86052 | E16: 36589 | F16: 153051 | G16: 105076 | H16: 582813 | I16: 332898 | J16: 99260 | K16: 150655 | L16: 34629 | M16: 31896 | N16: 15223 | O16: 1235081 | P16: -3138 | Q16: 1238219 | R16: 1220204 | S16: 589137 | T16: 631067 | U16: 2836 | V16: 2726 | W16: 26924 | X16: 87278
A17: Kyobo | B17: 2742682 | C17: 1450269 | D17: 778692 | E17: 102174 | F17: 303820 | G17: 107727 | H17: 2530495 | I17: 1423480 | J17: 780926 | K17: 326090 | L17: 22216 | M17: 19777 | N17: 26711 | O17: 6677690 | P17: 1573 | Q17: 6676117 | R17: 6061876 | S17: 2524540 | T17: 3537335 | U17: 24180 | V17: 19328 | W17: 205722 | X17: 602859
A18: DGB | B18: 183761 | C18: 63087 | D18: 18166 | E18: 4342 | F18: 43703 | G18: 54463 | H18: 115286 | I18: 59108 | J18: 19927 | K18: 36250 | L18: 32083 | M18: 28414 | N18: 12615 | O18: 416309 | P18: 23202 | Q18: 393108 | R18: 403538 | S18: 192157 | T18: 211381 | U18: 851 | V18: 6885 | W18: 11246 | X18: 55022
A19: MiraeAsset | B19: 676812 | C19: 325963 | D19: 71686 | E19: 35157 | F19: 148366 | G19: 95640 | H19: 515344 | I19: 317636 | J19: 65491 | K19: 132217 | L19: 15183 | M19: 16733 | N19: 48312 | O19: 2798236 | P19: 350130 | Q19: 2448106 | R19: 2701461 | S19: 1801958 | T19: 899503 | U19: 4957 | V19: 8442 | W19: 45664 | X19: 159231
A20: KDB | B20: 357041 | C20: 205130 | D20: 76859 | E20: 12639 | F20: 35250 | G20: 27164 | H20: 361521 | I20: 205989 | J20: 77633 | K20: 77900 | L20: 48499 | M20: 30140 | N20: 9242 | O20: 776368 | P20: 35861 | Q20: 740507 | R20: 782396 | S20: 458382 | T20: 324014 | U20: 1696 | V20: 18213 | W20: 0 | X20: -17908
A21: DB | B21: 467860 | C21: 172819 | D21: 67317 | E21: 11006 | F21: 102186 | G21: 114531 | H21: 374242 | I21: 212961 | J21: 70734 | K21: 90547 | L21: 32088 | M21: 32391 | N21: 9272 | O21: 667304 | P21: 62237 | Q21: 605067 | R21: 603054 | S21: 263093 | T21: 339961 | U21: 525 | V21: 2349 | W21: 31373 | X21: 115095
A22: Tongyang | B22: 824909 | C22: 388646 | D22: 133356 | E22: 33860 | F22: 194987 | G22: 74060 | H22: 624537 | I22: 379713 | J22: 131710 | K22: 113114 | L22: 17545 | M22: 14832 | N22: 19646 | O22: 1620706 | P22: 616 | Q22: 1620090 | R22: 1529518 | S22: 755002 | T22: 774516 | U22: 1057 | V22: 1279 | W22: 56913 | X22: 217494
A23: MetLife | B23: 669570 | C23: 198295 | D23: 104874 | E23: 23604 | F23: 152424 | G23: 190371 | H23: 477293 | I23: 192317 | J23: 93675 | K23: 191301 | L23: 7223 | M23: 12589 | N23: 8094 | O23: 2136029 | P23: -915 | Q23: 2136944 | R23: 2037911 | S23: 1082476 | T23: 955435 | U23: 848 | V23: -518 | W23: 56472 | X23: 221829
A24: KBLife | B24: 566025 | C24: 179207 | D24: 127550 | E24: 24345 | F24: 213050 | G24: 21873 | H24: 332037 | I24: 165917 | J24: 130417 | K24: 35703 | L24: 4043 | M24: 6764 | N24: 24190 | O24: 1587366 | P24: 161082 | Q24: 1426284 | R24: 1397487 | S24: 925182 | T24: 472305 | U24: 1628 | V24: 2333 | W24: 99378 | X24: 296874
... A38: 2023.2/4Q | B38: 15309840 | C38: 7712131 | D38: 2741668 | E38: 671012 | F38: 2966820 | G38: 1218208 | H38: 12084804 | I38: 7655121 | J38: 2806388 | K38: 1623295 | L38: 513052 | M38: 549348 | N38: 407804 | O38: 34480228 | P38: 859879 | Q38: 33620349 | R38: 32333546 | S38: 18515152 | T38: 13818394 | U38: 167604 | V38: 262310 | W38: 1003540 | X38: 3829374
A41: * Statement of Comprehensive Income is counted quarterly based on the Business Reports.

Sheet II-3
A2: II. Financial Statement
A3: II-3. Financial Statement of Separate Account(Earnings-Based Dividend)
A6: ='II-1'!A6 -> 2023. 11. 30. | Q6: unit: million won
B7: Balance Sheets | J7: Income Statement
B8: Assets | H8: Liabilities & Policyholder's Reserves | J8: Income | M8: Expenses
B10: Cash & Deposits | C10: Securities | D10: Loans | E10: Others | F10: Total Assets | G10: (Other Accounts Payable) | H10: Total Liabilities | I10: Policyholder's Reserves | J10: Premium Income | K10: Others | L10: Total Income | M10: Increase in Policyholder's Reserves | N10: Claims Paid | O10: S/A Opearting Commision | P10: Others | Q10: Total Expenses
A14: Hanwha | B14: 356982 | C14: 14207807 | D14: 452372 | E14: 299041 | F14: 15316203 | G14: 14790749 | H14: 15316203 | I14: 14489490 | J14: 877573 | K14: 1407204 | L14: 2284777 | M14: 81049 | N14: 973965 | O14: 545277 | P14: 684486 | Q14: 2284777
A15: ABL | B15: 228467 | C15: 1968755 | D15: 84046 | E15: 65694 | F15: 2346962 | G15: 2300212 | H15: 2346962 | I15: 2302208 | J15: 314231 | K15: 466852 | L15: 781083 | M15: 24462 | N15: 364331 | O15: 39863 | P15: 352426 | Q15: 781083
A16: Samsung | B16: 1035910 | C16: 24675022 | D16: 566596 | E16: 296768 | F16: 26574295 | G16: 26214399 | H16: 26574295 | I16: 26316189 | J16: 1614554 | K16: 2916734 | L16: 4531288 | M16: 445596 | N16: 1731621 | O16: 843650 | P16: 1510421 | Q16: 4531288
A17: Heungkuk | B17: 84670 | C17: 1068636 | D17: 83008 | E17: 41240 | F17: 1277555 | G17: 1227146 | H17: 1277555 | I17: 1248147 | J17: 151564 | K17: 713237 | L17: 864801 | M17: -32606 | N17: 239920 | O17: 39560 | P17: 617927 | Q17: 864801
A18: Kyobo | B18: 396654 | C18: 13726165 | D18: 471965 | E18: 325310 | F18: 14920094 | G18: 14837680 | H18: 14920094 | I18: 14806596 | J18: 1117791 | K18: 1583813 | L18: 2701604 | M18: 399872 | N18: 1049252 | O18: 430535 | P18: 821945 | Q18: 2701604
A19: DGB | B19: 106464 | C19: 951846 | D19: 0 | E19: 18712 | F19: 1077023 | G19: 1077023 | H19: 1077023 | I19: 1070457 | J19: 232891 | K19: 184988 | L19: 417879 | M19: 164120 | N19: 98037 | O19: 10570 | P19: 145152 | Q19: 417879
A20: MiraeAsset | B20: 451214 | C20: 11186520 | D20: 148550 | E20: 130315 | F20: 11916598 | G20: 11888048 | H20: 11916598 | I20: 11843313 | J20: 981684 | K20: 1548392 | L20: 2530076 | M20: 456422 | N20: 1342740 | O20: 230603 | P20: 500310 | Q20: 2530076
A21: KDB | B21: 20368 | C21: 625259 | D21: 47085 | E21: 21897 | F21: 714609 | G21: 680508 | H21: 714609 | I21: 695795 | J21: 133727 | K21: 64866 | L21: 198593 | M21: 72427 | N21: 78664 | O21: 15359 | P21: 32144 | Q21: 198593
A22: DB | B22: 62275 | C22: 1025831 | D22: 90603 | E22: 30381 | F22: 1209091 | G22: 1146090 | H22: 1209091 | I22: 1183504 | J22: 155089 | K22: 141382 | L22: 296471 | M22: 45365 | N22: 74112 | O22: 104742 | P22: 72252 | Q22: 296471
A23: Tongyang | B23: 59194 | C23: 1107954 | D23: 58683 | E23: 25956 | F23: 1251787 | G23: 1192965 | H23: 1251787 | I23: 1164573 | J23: 51423 | K23: 156720 | L23: 208144 | M23: 10806 | N23: 97930 | O23: 15164 | P23: 84244 | Q23: 208144
A24: MetLife | B24: 403005 | C24: 10179116 | D24: 418355 | E24: 174227 | F24: 11174703 | G24: 10804721 | H24: 11174703 | I24: 11088828 | J24: 1079373 | K24: 1606835 | L24: 2686208 | M24: 687990 | N24: 1188853 | O24: 140411 | P24: 668954 | Q24: 2686208
A25: KBLife | B25: 233964 | C25: 5159724 | D25: 135282 | E25: 124992 | F25: 5653961 | G25: 5579925 | H25: 5653961 | I25: 5580507 | J25: 520380 | K25: 588144 | L25: 1108524 | M25: 169397 | N25: 532900 | O25: 85450 | P25: 320776 | Q25: 1108524
... A37: Total | B37: 4135414 | C37: 94370473 | D37: 2815076 | E37: 1810694 | F37: 103131656 | G37: 101286707 | H37: 103131656 | I37: 101368042 | J37: 8114102 | K37: 12709558 | L37: 20823660 | M37: 2736377 | N37: 8946706 | O37: 2654506 | P37: 6486071 | Q37: 20823660
A39: ='I-2'!A37 -> 2023.10 | B39: 4339315 | C39: 96246128 | D39: 2872175 | E39: 2264928 | F39: 105722546 | G39: 104032054 | H39: 105722546 | I39: 103353019 | J39: 8114102 | K39: 12709558 | L39: 20823660 | M39: 2736377 | N39: 8946706 | O39: 2654506 | P39: 6486071 | Q39: 20823660
A40: ='I-2'!A38 -> 2023.9 | B40: 4031081 | C40: 97796687 | D40: 3036705 | E40: 2220973 | F40: 107085446 | G40: 105246694 | H40: 107091031 | I40: 105073851 | J40: 8114102 | K40: 12709558 | L40: 20823660 | M40: 2736377 | N40: 8946706 | O40: 2654506 | P40: 6486071 | Q40: 20823660
A41: ='I-2'!A39 -> 2023.8 | B41: 3966692 | C41: 97198314 | D41: 3279077 | E41: 2118576 | F41: 106562659 | G41: 104723238 | H41: 106562659 | I41: 104408602 | J41: 5437723 | K41: 11465256 | L41: 16902979 | M41: 5636846 | N41: 5745777 | O41: 1719018 | P41: 3801577 | Q41: 16903217
A44: * Income Statement is counted quarterly based on the Business Reports

Sheet III-1
A2: III. Income & Expenditure
A3: III-1. Premium Income by Insurance Type
A6: ='I-2'!A6 -> 2023. 1. 1. - 2023. 11. 30. | AT6: unit: million won
B7: General Account | W7: Separate Account
B8: Individual Insurance | Q8: Group Insurance | T8: Total Individual Insurance | W8: Guaranteed Investment Contract(GIC) | AI8: Earnings-Based Dividend | AR8: Total
B9: Coverage Insurance | H9: Savings Insurance | N9: Sub Total | Q9: First Premiums | R9: 2nd & Subsequent Premiums | S9: Sub Total | T9: First Premiums | U9: 2nd & Subsequent Premiums | V9: Sub Total | W9: Pension savings | Z9: Asset-Linked | AC9: Retirenment Pension | AF9: Sub Total | AI9: Variable | AL9: Retirenment Pension | AO9: Sub Total | AR9: First Premiums | AS9: 2nd & Subsequent Premiums | AT9: Sub Total
B10: Guaranteed Death Benefit | E10: Non-Guaranteed Death Benefit | H10: Annuity | K10: Excludin Annuity | N10: First Premiums | O10: 2nd & Subsequent Premiums | P10: Sub Total | W10: First Premiums | X10: 2nd & Subsequent Premiums | Y10: Sub Total | Z10: First Premiums | AA10: 2nd & Subsequent Premiums | AB10: Sub Total | AC10: First Premiums | AD10: 2nd & Subsequent Premiums | AE10: Sub Total | AF10: First Premiums | AG10: 2nd & Subsequent Premiums | AH10: Sub Total | AI10: First Premiums | AJ10: 2nd & Subsequent Premiums | AK10: Sub Total | AL10: First Premiums | AM10: 2nd & Subsequent Premiums | AN10: Sub Total | AO10: First Premiums | AP10: 2nd & Subsequent Premiums | AQ10: Sub Total
B11: First Premiums | C11: 2nd & Subsequent Premiums | D11: Sub Total | E11: First Premiums | F11: 2nd & Subsequent Premiums | G11: Sub Total | H11: First Premiums | I11: 2nd & Subsequent Premiums | J11: Sub Total | K11: First Premium | L11: 2nd & Subsequent Premiums | M11: Sub Total
A15: Hanwha | B15: 142776 | C15: 4491565 | D15: 4634341 | E15: 25206 | F15: 1469093 | G15: 1494298 | H15: 134844 | I15: 2223146 | J15: 2357990 | K15: 610 | L15: 238742 | M15: 239352 | N15: 303435 | O15: 8422547 | P15: 8725982 | Q15: 16736 | R15: 88536 | S15: 105272 | T15: 320171 | U15: 8511082 | V15: 8831253 | W15: 3258 | X15: 407004 | Y15: 410263 | Z15: 0 | AA15: 318 | AB15: 318 | AC15: 149703 | AD15: 645191 | AE15: 794894 | AF15: 152961 | AG15: 1052514 | AH15: 1205475 | AI15: 459 | AJ15: 1355566 | AK15: 1356025 | AL15: 156 | AM15: 506 | AN15: 662 | AO15: 615 | AP15: 1356071 | AQ15: 1356687 | AR15: 153576 | AS15: 2408585 | AT15: 2562161
A16: ABL | B16: 18727 | C16: 654872 | D16: 673599 | E16: 3427 | F16: 212960 | G16: 216386 | H16: 513987 | I16: 67090 | J16: 581077 | K16: 6455 | L16: 172329 | M16: 178784 | N16: 542596 | O16: 1107250 | P16: 1649846 | Q16: 11967 | R16: 1377 | S16: 13344 | T16: 554563 | U16: 1108628 | V16: 1663190 | W16: 53 | X16: 13517 | Y16: 13570 | Z16: 0 | AA16: 15350 | AB16: 15350 | AC16: 0 | AD16: 0 | AE16: 0 | AF16: 53 | AG16: 28867 | AH16: 28920 | AI16: 5126 | AJ16: 457321 | AK16: 462447 | AL16: 0 | AM16: 0 | AN16: 0 | AO16: 5126 | AP16: 457321 | AQ16: 462447 | AR16: 5179 | AS16: 486187 | AT16: 491367
A17: Samsung | B17: 138008 | C17: 7578922 | D17: 7716930 | E17: 44876 | F17: 2405265 | G17: 2450141 | H17: 2939321 | I17: 1621269 | J17: 4560590 | K17: 64529 | L17: 301271 | M17: 365800 | N17: 3186735 | O17: 11906726 | P17: 15093461 | Q17: 40524 | R17: 344229 | S17: 384753 | T17: 3227259 | U17: 12250955 | V17: 15478214 | W17: 7719 | X17: 937431 | Y17: 945151 | Z17: 0 | AA17: 54 | AB17: 54 | AC17: 154372 | AD17: 3245085 | AE17: 3399457 | AF17: 162091 | AG17: 4182570 | AH17: 4344662 | AI17: 23475 | AJ17: 2007999 | AK17: 2031474 | AL17: 14 | AM17: 25330 | AN17: 25344 | AO17: 23490 | AP17: 2033328 | AQ17: 2056818 | AR17: 185581 | AS17: 6215899 | AT17: 6401480
A18: Heungkuk | B18: 11830 | C18: 683741 | D18: 695572 | E18: 1242 | F18: 727214 | G18: 728456 | H18: 9055 | I18: 41877 | J18: 50933 | K18: 283119 | L18: 325001 | M18: 608120 | N18: 305247 | O18: 1777833 | P18: 2083080 | Q18: 5 | R18: 1238 | S18: 1243 | T18: 305252 | U18: 1779071 | V18: 2084323 | W18: 3 | X18: 16033 | Y18: 16037 | Z18: 0 | AA18: 3376 | AB18: 3376 | AC18: 556234 | AD18: 26131 | AE18: 582365 | AF18: 556237 | AG18: 45540 | AH18: 601778 | AI18: 7947 | AJ18: 176006 | AK18: 183952 | AL18: 1639 | AM18: 1584 | AN18: 3223 | AO18: 9586 | AP18: 177590 | AQ18: 187175 | AR18: 565823 | AS18: 223130 | AT18: 788953
A19: Kyobo | B19: 60273 | C19: 3523689 | D19: 3583962 | E19: 19990 | F19: 934505 | G19: 954495 | H19: 3879910 | I19: 848174 | J19: 4728083 | K19: 3215 | L19: 643210 | M19: 646424 | N19: 3963388 | O19: 5949577 | P19: 9912964 | Q19: 23932 | R19: 115782 | S19: 139714 | T19: 3987320 | U19: 6065358 | V19: 10052678 | W19: 1490 | X19: 282281 | Y19: 283770 | Z19: 0 | AA19: 4 | AB19: 4 | AC19: 463577 | AD19: 1490469 | AE19: 1954047 | AF19: 465067 | AG19: 1772754 | AH19: 2237821 | AI19: 3894 | AJ19: 1437806 | AK19: 1441700 | AL19: 149 | AM19: 16295 | AN19: 16444 | AO19: 4044 | AP19: 1454101 | AQ19: 1458144 | AR19: 469111 | AS19: 3226855 | AT19: 3695965
A20: DGB | B20: 17599 | C20: 320287 | D20: 337886 | E20: 1403 | F20: 70708 | G20: 72111 | H20: 1556 | I20: 31763 | J20: 33319 | K20: 124 | L20: 56264 | M20: 56388 | N20: 20681 | O20: 479023 | P20: 499704 | Q20: 3424 | R20: 1673 | S20: 5097 | T20: 24106 | U20: 480695 | V20: 504801 | W20: 0 | X20: 2237 | Y20: 2237 | Z20: 0 | AA20: 0 | AB20: 0 | AC20: 0 | AD20: 0 | AE20: 0 | AF20: 0 | AG20: 2237 | AH20: 2237 | AI20: 59435 | AJ20: 251919 | AK20: 311354 | AL20: 0 | AM20: 0 | AN20: 0 | AO20: 59435 | AP20: 251919 | AQ20: 311354 | AR20: 59435 | AS20: 254156 | AT20: 313591
A21: MiraeAsset | B21: 11480 | C21: 810515 | D21: 821995 | E21: 2655 | F21: 348543 | G21: 351198 | H21: 0 | I21: 47578 | J21: 47578 | K21: 0 | L21: 20631 | M21: 20631 | N21: 14135 | O21: 1227267 | P21: 1241402 | Q21: 33 | R21: 13665 | S21: 13698 | T21: 14168 | U21: 1240932 | V21: 1255100 | W21: 0 | X21: 42229 | Y21: 42229 | Z21: 0 | AA21: 1422 | AB21: 1422 | AC21: 91431 | AD21: 458314 | AE21: 549745 | AF21: 91431 | AG21: 501965 | AH21: 593396 | AI21: 98827 | AJ21: 1217306 | AK21: 1316133 | AL21: 4324 | AM21: 23175 | AN21: 27499 | AO21: 103151 | AP21: 1240481 | AQ21: 1343632 | AR21: 194582 | AS21: 1742446 | AT21: 1937028
A22: KDB | B22: 15330 | C22: 796293 | D22: 811623 | E22: 3299 | F22: 292807 | G22: 296106 | H22: 53 | I22: 307743 | J22: 307796 | K22: -7551 | L22: 232724 | M22: 225173 | N22: 11130 | O22: 1629567 | P22: 1640698 | Q22: 259 | R22: 10692 | S22: 10951 | T22: 11390 | U22: 1640259 | V22: 1651649 | W22: 276 | X22: 41971 | Y22: 42247 | Z22: 0 | AA22: 5810 | AB22: 5810 | AC22: 0 | AD22: 0 | AE22: 0 | AF22: 276 | AG22: 47781 | AH22: 48057 | AI22: 6760 | AJ22: 177970 | AK22: 184731 | AL22: 0 | AM22: 0 | AN22: 0 | AO22: 6760 | AP22: 177970 | AQ22: 184731 | AR22: 7037 | AS22: 225751 | AT22: 232788
A23: DB | B23: 28391 | C23: 927962 | D23: 956352 | E23: 7141 | F23: 436316 | G23: 443457 | H23: 2177 | I23: 25543 | J23: 27720 | K23: 1 | L23: 25876 | M23: 25876 | N23: 37709 | O23: 1415697 | P23: 1453406 | Q23: 0 | R23: 57 | S23: 57 | T23: 37709 | U23: 1415754 | V23: 1453463 | W23: 0 | X23: 298 | Y23: 298 | Z23: 0 | AA23: 708 | AB23: 708 | AC23: 9566 | AD23: 46259 | AE23: 55825 | AF23: 9566 | AG23: 47265 | AH23: 56831 | AI23: 28 | AJ23: 195200 | AK23: 195228 | AL23: 0 | AM23: 0 | AN23: 0 | AO23: 28 | AP23: 195200 | AQ23: 195228 | AR23: 9594 | AS23: 242465 | AT23: 252059
A24: Tongyang | B24: 41690 | C24: 1251356 | D24: 1293046 | E24: 19697 | F24: 915997 | G24: 935695 | H24: 436993 | I24: 230445 | J24: 667437 | K24: -7138 | L24: 412162 | M24: 405025 | N24: 491243 | O24: 2809960 | P24: 3301203 | Q24: 0 | R24: 623 | S24: 623 | T24: 491243 | U24: 2810582 | V24: 3301825 | W24: 171 | X24: 22931 | Y24: 23102 | Z24: 0 | AA24: 92 | AB24: 92 | AC24: 13906 | AD24: 504114 | AE24: 518019 | AF24: 14077 | AG24: 527137 | AH24: 541213 | AI24: 97 | AJ24: 121834 | AK24: 121931 | AL24: 0 | AM24: 850 | AN24: 850 | AO24: 97 | AP24: 122683 | AQ24: 122781 | AR24: 14174 | AS24: 649820 | AT24: 663994
A25: MetLife | B25: 29737 | C25: 891263 | D25: 920999 | E25: 423 | F25: 99222 | G25: 99645 | H25: 788 | I25: 24144 | J25: 24933 | K25: 0 | L25: 6967 | M25: 6967 | N25: 30948 | O25: 1021595 | P25: 1052544 | Q25: 0 | R25: 3 | S25: 3 | T25: 30948 | U25: 1021599 | V25: 1052547 | W25: 0 | X25: 7 | Y25: 7 | Z25: 239789 | AA25: 1934 | AB25: 241723 | AC25: 0 | AD25: 0 | AE25: 0 | AF25: 241180 | AG25: 5065 | AH25: 246245 | AI25: 75255 | AJ25: 1656821 | AK25: 1732076 | AL25: 0 | AM25: 0 | AN25: 0 | AO25: 75255 | AP25: 1656821 | AQ25: 1732076 | AR25: 316435 | AS25: 1661886 | AT25: 1978321
A26: KBLife | B26: 43904 | C26: 1708017 | D26: 1751922 | E26: 431 | F26: 63956 | G26: 64387 | H26: 8355 | I26: 601148 | J26: 609503 | K26: 21853 | L26: 15002 | M26: 36855 | N26: 74543 | O26: 2388124 | P26: 2462667 | Q26: 1379 | R26: 0 | S26: 1379 | T26: 75922 | U26: 2388125 | V26: 2464046 | W26: 0 | X26: 8172 | Y26: 8172 | Z26: 0 | AA26: 968 | AB26: 968 | AC26: 16849 | AD26: 270026 | AE26: 286876 | AF26: 16973 | AG26: 279409 | AH26: 296382 | AI26: 57699 | AJ26: 743339 | AK26: 801038 | AL26: 0 | AM26: 0 | AN26: 0 | AO26: 57699 | AP26: 743339 | AQ26: 801038 | AR26: 74672 | AS26: 1022748 | AT26: 1097420
... A38: Total | B38: 671531 | C38: 29145189 | D38: 29816720 | E38: 327603 | F38: 13673472 | G38: 14001075 | H38: 9513073 | I38: 8287249 | J38: 17800322 | K38: 846020 | L38: 3375209 | M38: 4221229 | N38: 11358227 | O38: 54481119 | P38: 65839346 | Q38: 113141 | R38: 579696 | S38: 692837 | T38: 11471368 | U38: 55060815 | V38: 66532183 | W38: 17646 | X38: 2549976 | Y38: 2567622 | Z38: 1425997 | AA38: 50805 | AB38: 1476802 | AC38: 2261868 | AD38: 9378197 | AE38: 11640064 | AF38: 3707026 | AG38: 11982343 | AH38: 15689370 | AI38: 486651 | AJ38: 10760780 | AK38: 11247431 | AL38: 6905 | AM38: 71168 | AN38: 78073 | AO38: 493556 | AP38: 10831948 | AQ38: 11325504 | AR38: 4200582 | AS38: 22814291 | AT38: 27014873
A40: ='I-2'!A37 -> 2023.10 | B40: 621324 | C40: 26335155 | D40: 26956479 | E40: 304690 | F40: 12414497 | G40: 12719187 | H40: 8264717 | I40: 7622174 | J40: 15886892 | K40: 841526 | L40: 3136165 | M40: 3977691 | N40: 10032258 | O40: 49507991 | P40: 59540249 | Q40: 107555 | R40: 527225 | S40: 634780 | T40: 10139813 | U40: 50035215 | V40: 60175028 | W40: 16502 | X40: 2316975 | Y40: 2333477 | Z40: 1225838 | AA40: 46864 | AB40: 1272702 | AC40: 1959441 | AD40: 8263634 | AE40: 10223075 | AF40: 3203069 | AG40: 10629624 | AH40: 13832693 | AI40: 443784 | AJ40: 9839814 | AK40: 10283598 | AL40: 6455 | AM40: 66556 | AN40: 73011 | AO40: 450238 | AP40: 9906371 | AQ40: 10356609 | AR40: 3653307 | AS40: 20535995 | AT40: 24189302
A41: ='I-2'!A38 -> 2023.9 | B41: 575749 | C41: 23532202 | D41: 24107950 | E41: 282691 | F41: 11153380 | G41: 11436071 | H41: 7454968 | I41: 6950727 | J41: 14405695 | K41: 846963 | L41: 2889189 | M41: 3736152 | N41: 9160371 | O41: 44525498 | P41: 53685868 | Q41: 99164 | R41: 474668 | S41: 573832 | T41: 9259535 | U41: 45000166 | V41: 54259701 | W41: 15561 | X41: 2087543 | Y41: 2103104 | Z41: 1166796 | AA41: 42749 | AB41: 1209545 | AC41: 1685012 | AD41: 7817779 | AE41: 9502791 | AF41: 2868386 | AG41: 9949203 | AH41: 12817588 | AI41: 410738 | AJ41: 8903005 | AK41: 9313742 | AL41: 6109 | AM41: 61800 | AN41: 67909 | AO41: 416847 | AP41: 8964804 | AQ41: 9381651 | AR41: 3285233 | AS41: 18914007 | AT41: 22199240
A42: ='I-2'!A39 -> 2023.8 | B42: 532212 | C42: 20754402 | D42: 21286614 | E42: 259274 | F42: 9904131 | G42: 10163405 | H42: 6668570 | I42: 6267133 | J42: 12935703 | K42: 842151 | L42: 2618940 | M42: 3461091 | N42: 8302207 | O42: 39544606 | P42: 47846813 | Q42: 92953 | R42: 422566 | S42: 515519 | T42: 8395161 | U42: 39967172 | V42: 48362332 | W42: 14440 | X42: 1858210 | Y42: 1872649 | Z42: 989743 | AA42: 38634 | AB42: 1028378 | AC42: 1512013 | AD42: 7340020 | AE42: 8852033 | AF42: 2516987 | AG42: 9237255 | AH42: 11754242 | AI42: 339384 | AJ42: 7969028 | AK42: 8308411 | AL42: 5598 | AM42: 56333 | AN42: 61932 | AO42: 344982 | AP42: 8025361 | AQ42: 8370343 | AR42: 2861969 | AS42: 17262616 | AT42: 20124585

Sheet III-2
A2: III. Income & Expenditure
A3: III-2. Premium Income by Source of Distribution
A6: ='III-1'!A6 -> 2023. 1. 1. - 2023. 11. 30. | W6: unit: million won
B7: First Premium by type of solicitation | K7: 2nd & Subsequent Premiums by receive method | T7: Premium by Method of Payments
B8: Face to Face | H8: T/M | I8: C/M | K8: Consultant | L8: GIRO | M8: Automation Transfer | N8: Agencies | O8: Direct Payment | P8: Credit Card | Q8: Bancassurance | R8: Other | S8: Sub Total | T8: Single Payment | U8: Monthly Payment | V8: Other | W8: Total
B9: Consultant | C9: Agencies | D9: Insurance Agencies of Financial Institutions | E9: Company Staff | F9: Other | G9: Sub Total | J9: Insurance Agencies of Financial Institutions
A14: Hanwha | B14: 0 | C14: 201177 | D14: 103465 | E14: 17865 | F14: 0 | G14: 322507 | H14: -1 | I14: 1382 | J14: 0 | K14: 279635 | L14: 865 | M14: 7729599 | N14: 0 | O14: 0 | P14: 0 | Q14: 2072309 | R14: 191562 | S14: 10273970 | T14: 86131 | U14: 225454 | V14: 12303 | W14: 323888
A15: ABL | B15: 14423 | C15: 18012 | D15: 515268 | E15: 930 | F15: 10899 | G15: 559532 | H15: 0 | I15: 210 | J15: 0 | K15: 23468 | L15: 204 | M15: 1559994 | N15: 4536 | O15: 1038 | P15: 3776 | Q15: 205 | R15: 1595 | S15: 1594815 | T15: 518782 | U15: 29025 | V15: 11935 | W15: 559742
A16: Samsung | B16: 440327 | C16: 132215 | D16: 2647155 | E16: 32129 | F16: 0 | G16: 3251825 | H16: 0 | I16: 6628 | J16: 0 | K16: 56751 | L16: 753 | M16: 14043665 | N16: 13951 | O16: 0 | P16: 52131 | Q16: 345006 | R16: 684182 | S16: 15196438 | T16: 3006997 | U16: 219005 | V16: 32452 | W16: 3258454
A17: Heungkuk | B17: 1845 | C17: 10966 | D17: 298204 | E17: 9 | F17: 0 | G17: 311024 | H17: 2175 | I17: 3 | J17: 0 | K17: 11129 | L17: 197 | M17: 1871851 | N17: 0 | O17: 0 | P17: 91309 | Q17: 0 | R17: 0 | S17: 1974486 | T17: 298783 | U17: 14352 | V17: 67 | W17: 313202
A18: Kyobo | B18: 377280 | C18: 71770 | D18: 3519065 | E18: 21848 | F18: 0 | G18: 3989962 | H18: 2724 | I18: 17 | J18: 0 | K18: 195416 | L18: 1782 | M18: 6412674 | N18: 34420 | O18: 23321 | P18: 0 | Q18: 1117836 | R18: 0 | S18: 7785449 | T18: 3861290 | U18: 110126 | V18: 21288 | W18: 3992703
A19: DGB | B19: 265 | C19: 67642 | D19: 11058 | E19: 3473 | F19: 0 | G19: 82438 | H19: 976 | I19: 127 | J19: 0 | K19: 0 | L19: 0 | M19: 703677 | N19: 0 | O19: 10546 | P19: 20361 | Q19: 0 | R19: 267 | S19: 734852 | T19: 56804 | U19: 22312 | V19: 4425 | W19: 83540
A20: MiraeAsset | B20: 0 | C20: 49982 | D20: 62674 | E20: 1 | F20: 0 | G20: 112657 | H20: 0 | I20: 338 | J20: 0 | K20: 0 | L20: 2730 | M20: 2163688 | N20: 0 | O20: 2444 | P20: 53213 | Q20: 279815 | R20: 0 | S20: 2501890 | T20: 92378 | U20: 20613 | V20: 4 | W20: 112995
A21: KDB | B21: 6727 | C21: 14359 | D21: -3020 | E21: 8 | F21: 0 | G21: 18074 | H21: 138 | I21: 215 | J21: 0 | K21: 5033 | L21: 0 | M21: 1659186 | N21: 3117 | O21: 3944 | P21: 32188 | Q21: 0 | R21: 162541 | S21: 1866010 | T21: -5648 | U21: 21272 | V21: 2803 | W21: 18427
A22: DB | B22: 2766 | C22: 31081 | D22: 3109 | E22: 195 | F22: 0 | G22: 37152 | H22: 584 | I22: 1 | J22: 0 | K22: 0 | L22: 141 | M22: 1502989 | N22: 0 | O22: 9856 | P22: 29867 | Q22: 69107 | R22: 0 | S22: 1611960 | T22: 2644 | U22: 34717 | V22: 376 | W22: 37737
A23: Tongyang | B23: 16222 | C23: 36358 | D23: 379229 | E23: 51 | F23: 0 | G23: 431860 | H23: 3941 | I23: 55710 | J23: 55771 | K23: 1974 | L23: 42 | M23: 2516484 | N23: 1219 | O23: 29642 | P23: 389246 | Q23: 0 | R23: 16831 | S23: 2955438 | T23: 427412 | U23: 53116 | V23: 10984 | W23: 491511
A24: MetLife | B24: 156105 | C24: 41513 | D24: 148343 | E24: 11 | F24: 0 | G24: 345972 | H24: 0 | I24: 20 | J24: 0 | K24: 57556 | L24: 46 | M24: 2612593 | N24: 0 | O24: 0 | P24: 730 | Q24: 334 | R24: 9101 | S24: 2680361 | T24: 309386 | U24: 36605 | V24: 1 | W24: 345992
A25: KBLife | B25: 1911 | C25: 69962 | D25: 58495 | E25: 0 | F25: 1379 | G25: 131747 | H25: 182 | I25: 1692 | J25: 1515 | K25: 0 | L25: 392 | M25: 2841887 | N25: 0 | O25: 31225 | P25: 267100 | Q25: 0 | R25: 0 | S25: 3140604 | T25: 78900 | U25: 52755 | V25: 1965 | W25: 133621
... A37: Total | B37: 1112610 | C37: 854544 | D37: 11098960 | E37: 91940 | F37: 12278 | G37: 13170332 | H37: 50948 | I37: 180382 | J37: 167885 | K37: 640592 | L37: 7199 | M37: 57726044 | N37: 57243 | O37: 699340 | P37: 3046817 | Q37: 4536587 | R37: 1708552 | S37: 68422375 | T37: 12113701 | U37: 1043700 | V37: 244261 | W37: 13401662
A39: ='I-2'!A37 -> 2023.10 | B39: 965400 | C39: 778042 | D39: 9798093 | E39: 87552 | F39: 12162 | G39: 11641248 | H39: 46005 | I39: 138683 | J39: 127230 | K39: 582621 | L39: 6560 | M39: 52447909 | N39: 51718 | O39: 628214 | P39: 2757312 | Q39: 4214978 | R39: 1549557 | S39: 62238869 | T39: 10629328 | U39: 961180 | V39: 235428 | W39: 11825937
A40: ='I-2'!A38 -> 2023.9 | B40: 869547 | C40: 730697 | D40: 8991565 | E40: 79900 | F40: 12057 | G40: 10683766 | H40: 41636 | I40: 127227 | J40: 116634 | K40: 522289 | L40: 5941 | M40: 47154269 | N40: 47258 | O40: 559180 | P40: 2467251 | Q40: 3888555 | R40: 1388719 | S40: 56033463 | T40: 9741815 | U40: 886493 | V40: 224321 | W40: 10852629
A41: ='I-2'!A39 -> 2023.8 | B41: 751252 | C41: 649446 | D41: 8092534 | E41: 74651 | F41: 11967 | G41: 9579850 | H41: 37482 | I41: 121396 | J41: 111661 | K41: 471295 | L41: 5291 | M41: 41848419 | N41: 43420 | O41: 500207 | P41: 2181514 | Q41: 3550600 | R41: 1232297 | S41: 49833043 | T41: 8713454 | U41: 811370 | V41: 213903 | W41: 9738727
A43: ※General Account Performance excluding Retirement Pension

Sheet III-3
A2: III. Income & Expenditure
A3: III-3. Benefit Payments·Refunds & Dividends
A6: ='III-2'!A6 -> 2023. 1. 1. - 2023. 11. 30. | P6: unit: million won
B7: Benefit Payment | G7: Refunds | O7: Dividends | P7: Total
B8: Death | C8: Accident | D8: Matured | E8: Retirement | F8: Sub Total | G8: Surrenders | H8: Lapses | I8: Death Benefits | J8: Hospitalization | K8: Accident | L8: Pure Endowment | M8: Others | N8: Sub Total
A11: Hanwha | B11: 360552 | C11: 7107 | D11: 2375343 | E11: 0 | F11: 2743002 | G11: 4889303 | H11: 221317 | I11: 29626 | J11: 1792610 | K11: 47581 | L11: 1510591 | M11: 2840 | N11: 8493869 | O11: 38127 | P11: 11274998
A12: ABL | B12: 64310 | C12: 2714 | D12: 455011 | E12: 0 | F12: 522036 | G12: 1171545 | H12: 47053 | I12: 2616 | J12: 257614 | K12: 6146 | L12: 397294 | M12: 14805 | N12: 1897072 | O12: 1509 | P12: 2420617
A13: Samsung | B13: 965977 | C13: 41992 | D13: 3392447 | E13: 0 | F13: 4400416 | G13: 9382665 | H13: 226699 | I13: 94412 | J13: 2804009 | K13: 58041 | L13: 4592733 | M13: 23905 | N13: 17182462 | O13: 49188 | P13: 21632067
A14: Heungkuk | B14: 71246 | C14: 536 | D14: 658615 | E14: 0 | F14: 730397 | G14: 1474824 | H14: 42990 | I14: 8777 | J14: 305859 | K14: 1214 | L14: 920615 | M14: 539 | N14: 2754817 | O14: 10088 | P14: 3495302
A15: Kyobo | B15: 299605 | C15: 4255 | D15: 1230041 | E15: 0 | F15: 1533901 | G15: 4697396 | H15: 180043 | I15: 31123 | J15: 1315481 | K15: 37910 | L15: 1919103 | M15: 6013 | N15: 8187069 | O15: 14493 | P15: 9735462
A16: DGB | B16: 9821 | C16: 817 | D16: 83691 | E16: 0 | F16: 94329 | G16: 438716 | H16: 19226 | I16: 0 | J16: 62415 | K16: 1009 | L16: 117260 | M16: 5676 | N16: 644302 | O16: 0 | P16: 738631
A17: MiraeAsset | B17: 56471 | C17: 2570 | D17: 283101 | E17: 0 | F17: 342141 | G17: 775067 | H17: 37119 | I17: 130 | J17: 318544 | K17: 5516 | L17: 443512 | M17: 37573 | N17: 1617461 | O17: 1638 | P17: 1961240
A18: KDB | B18: 56382 | C18: 754 | D18: 354963 | E18: 0 | F18: 412098 | G18: 1278948 | H18: 38238 | I18: 8030 | J18: 167637 | K18: 2990 | L18: 163770 | M18: 163296 | N18: 1822909 | O18: 2202 | P18: 2237210
A19: DB | B19: 33499 | C19: 384 | D19: 158516 | E19: 0 | F19: 192399 | G19: 477833 | H19: 25004 | I19: 7253 | J19: 183456 | K19: 3139 | L19: 31585 | M19: 88063 | N19: 816333 | O19: 1647 | P19: 1010379
A20: Tongyang | B20: 66069 | C20: 3373 | D20: 1517524 | E20: 0 | F20: 1586967 | G20: 2023641 | H20: 79314 | I20: 82 | J20: 378813 | K20: 5817 | L20: 674236 | M20: 19725 | N20: 3181628 | O20: 1373 | P20: 4769967
A21: MetLife | B21: 62265 | C21: 2672 | D21: 101550 | E21: 0 | F21: 166487 | G21: 1193884 | H21: 64263 | I21: 2723 | J21: 172993 | K21: 7423 | L21: 630923 | M21: 13480 | N21: 2085688 | O21: 457 | P21: 2252631
A22: KBLife | B22: 77703 | C22: 69 | D22: 136286 | E22: 0 | F22: 214059 | G22: 1778500 | H22: 91622 | I22: 3963 | J22: 135440 | K22: 4307 | L22: 394993 | M22: 133158 | N22: 2541981 | O22: 3801 | P22: 2759840
... A34: Total | B34: 2736376 | C34: 79563 | D34: 14160636 | E34: 0 | F34: 16976574 | G34: 40573943 | H34: 1482262 | I34: 303830 | J34: 10806493 | K34: 242248 | L34: 14717277 | M34: 658143 | N34: 68784196 | O34: 160702 | P34: 85921473
A36: ='I-2'!A37 -> 2023.10 | B36: 2475077 | C36: 70724 | D36: 13154940 | E36: 0 | F36: 15700742 | G36: 37095262 | H36: 1340433 | I36: 278753 | J36: 9769817 | K36: 219232 | L36: 13528991 | M36: 601296 | N36: 62833785 | O36: 142318 | P36: 78676845
A37: ='I-2'!A38 -> 2023.9 | B37: 2231215 | C37: 64470 | D37: 12133521 | E37: 0 | F37: 14429206 | G37: 33850619 | H37: 1212506 | I37: 251665 | J37: 8837535 | K37: 199624 | L37: 12321136 | M37: 546640 | N37: 57219725 | O37: 130773 | P37: 71779703
A38: ='I-2'!A39 -> 2023.8 | B38: 2001680 | C38: 57756 | D38: 11178671 | E38: 0 | F38: 13238107 | G38: 30819720 | H38: 1094384 | I38: 225763 | J38: 7913118 | K38: 179390 | L38: 11195434 | M38: 490513 | N38: 51918321 | O38: 120285 | P38: 65276713
A40: ※General Account Performance excluding Retirement Pension

Sheet Ⅳ-1
A2: Ⅳ. Business Status
A3: Ⅳ-1. Business Results
A6: ='III-3'!A6 -> 2023. 1. 1. - 2023. 11. 30. | U6: unit: no. of policies, million won
B7: Business in Force at the Beginning of the Fiscal Year | D7: New Business | F7: Reinstatment | H7: Other Increases | J7: Eventinsured against | L7: Matured | N7: Retirement | P7: Lapses & Surrenders | R7: Other Decreases | T7: Business in Force at the End of the Fiscal Year
B10: No. | C10: Amount | D10: No. | E10: Amount | F10: No. | G10: Amount | H10: No. | I10: Amount | J10: No. | K10: Amount | L10: No. | M10: Amount | N10: No. | O10: Amount | P10: No. | Q10: Amount | R10: No. | S10: Amount | T10: No. | U10: Amount
A12: Hanwha | B12: 10165443 | C12: 300725915 | D12: 1260811 | E12: 26967598 | F12: 6066 | G12: 231102 | H12: 109706 | I12: 2214870 | J12: 15566 | K12: 395189 | L12: 527235 | M12: 4191401 | N12: 0 | O12: 0 | P12: 689676 | Q12: 21576624 | R12: 92800 | S12: 3315893 | T12: 10216749 | U12: 300660377
